Traceback (most recent call last):
  File "/home/fayabase/test.fayabase.com/flask_project/passenger_wsgi.py", line 9, in <module>
    application = wsgi.app
AttributeError: module 'wsgi' has no attribute 'app'
Traceback (most recent call last):
  File "/home/fayabase/test.fayabase.com/flask_project/passenger_wsgi.py", line 9, in <module>
    application = wsgi.app
AttributeError: module 'wsgi' has no attribute 'app'
[UID:1801][4097686] Child process with pid: 4097750 was killed by signal: 15, core dumped: no
Traceback (most recent call last):
  File "/home/fayabase/test.fayabase.com/flask_project/passenger_wsgi.py", line 9, in <module>
    application = wsgi.app
AttributeError: module 'wsgi' has no attribute 'app'
[UID:1801][4097686] Child process with pid: 4097769 was killed by signal: 15, core dumped: no
Traceback (most recent call last):
  File "/home/fayabase/test.fayabase.com/flask_project/passenger_wsgi.py", line 9, in <module>
    application = wsgi.app
AttributeError: module 'wsgi' has no attribute 'app'
[UID:1801][4097686] Child process with pid: 4097990 was killed by signal: 15, core dumped: no
Traceback (most recent call last):
  File "/home/fayabase/test.fayabase.com/flask_project/passenger_wsgi.py", line 9, in <module>
    application = wsgi.app
AttributeError: module 'wsgi' has no attribute 'app'
[UID:1801][4097686] Child process with pid: 4098000 was killed by signal: 15, core dumped: no
Traceback (most recent call last):
  File "/home/fayabase/test.fayabase.com/flask_project/passenger_wsgi.py", line 9, in <module>
    application = wsgi.app
AttributeError: module 'wsgi' has no attribute 'app'
[UID:1801][4097686] Child process with pid: 4101797 was killed by signal: 15, core dumped: no
Traceback (most recent call last):
  File "/home/fayabase/test.fayabase.com/flask_project/passenger_wsgi.py", line 9, in <module>
    application = wsgi.app
AttributeError: module 'wsgi' has no attribute 'app'
[UID:1801][4097686] Child process with pid: 4101827 was killed by signal: 15, core dumped: no
Traceback (most recent call last):
  File "/home/fayabase/test.fayabase.com/flask_project/passenger_wsgi.py", line 9, in <module>
    application = wsgi.app
AttributeError: module 'wsgi' has no attribute 'app'
[UID:1801][4097686] Child process with pid: 4102098 was killed by signal: 15, core dumped: no
Traceback (most recent call last):
  File "/home/fayabase/test.fayabase.com/flask_project/passenger_wsgi.py", line 9, in <module>
    application = wsgi.app
AttributeError: module 'wsgi' has no attribute 'app'
[UID:1801][4097686] Child process with pid: 4102130 was killed by signal: 15, core dumped: no
Traceback (most recent call last):
  File "/home/fayabase/test.fayabase.com/flask_project/passenger_wsgi.py", line 9, in <module>
    application = wsgi.app
AttributeError: module 'wsgi' has no attribute 'app'
Traceback (most recent call last):
  File "/home/fayabase/test.fayabase.com/flask_project/passenger_wsgi.py", line 9, in <module>
    application = wsgi.app
AttributeError: module 'wsgi' has no attribute 'app'
[UID:1801][4128595] Child process with pid: 4128630 was killed by signal: 15, core dumped: no
Traceback (most recent call last):
  File "/home/fayabase/test.fayabase.com/flask_project/passenger_wsgi.py", line 9, in <module>
    application = wsgi.app
AttributeError: module 'wsgi' has no attribute 'app'
[UID:1801][4128595] Child process with pid: 4128641 was killed by signal: 15, core dumped: no
Traceback (most recent call last):
  File "/home/fayabase/test.fayabase.com/flask_project/passenger_wsgi.py", line 9, in <module>
    application = wsgi.app
AttributeError: module 'wsgi' has no attribute 'app'
[UID:1801][4128595] Child process with pid: 4129754 was killed by signal: 15, core dumped: no
Traceback (most recent call last):
  File "/home/fayabase/test.fayabase.com/flask_project/passenger_wsgi.py", line 9, in <module>
    application = wsgi.app
AttributeError: module 'wsgi' has no attribute 'app'
[UID:1801][4128595] Child process with pid: 4129755 was killed by signal: 15, core dumped: no
Traceback (most recent call last):
  File "/home/fayabase/test.fayabase.com/flask_project/passenger_wsgi.py", line 9, in <module>
    application = wsgi.app
AttributeError: module 'wsgi' has no attribute 'app'
Traceback (most recent call last):
  File "/home/fayabase/test.fayabase.com/flask_project/passenger_wsgi.py", line 9, in <module>
    application = wsgi.app
AttributeError: module 'wsgi' has no attribute 'app'
[UID:1801][4130184] Child process with pid: 4130200 was killed by signal: 15, core dumped: no
Traceback (most recent call last):
  File "/home/fayabase/test.fayabase.com/flask_project/passenger_wsgi.py", line 9, in <module>
    application = wsgi.app
AttributeError: module 'wsgi' has no attribute 'app'
[UID:1801][4130184] Child process with pid: 4130201 was killed by signal: 15, core dumped: no
[2024-11-21 01:37:37,526] ERROR in app: Exception on /save [POST]
Traceback (most recent call last):
  File "/home/fayabase/virtualenv/test.fayabase.com/flask_project/3.8/lib/python3.8/site-packages/flask/app.py", line 1473, in wsgi_app
    response = self.full_dispatch_request()
  File "/home/fayabase/virtualenv/test.fayabase.com/flask_project/3.8/lib/python3.8/site-packages/flask/app.py", line 882, in full_dispatch_request
    rv = self.handle_user_exception(e)
  File "/home/fayabase/virtualenv/test.fayabase.com/flask_project/3.8/lib/python3.8/site-packages/flask/app.py", line 880, in full_dispatch_request
    rv = self.dispatch_request()
  File "/home/fayabase/virtualenv/test.fayabase.com/flask_project/3.8/lib/python3.8/site-packages/flask/app.py", line 865, in dispatch_request
    return self.ensure_sync(self.view_functions[rule.endpoint])(**view_args)  # type: ignore[no-any-return]
  File "/home/fayabase/test.fayabase.com/flask_project/application.py", line 21, in save_design
    random_filename = f"{uuid.uuid4().hex}.png"
NameError: name 'uuid' is not defined
[2024-11-21 01:38:12,998] ERROR in app: Exception on /save [POST]
Traceback (most recent call last):
  File "/home/fayabase/virtualenv/test.fayabase.com/flask_project/3.8/lib/python3.8/site-packages/flask/app.py", line 1473, in wsgi_app
    response = self.full_dispatch_request()
  File "/home/fayabase/virtualenv/test.fayabase.com/flask_project/3.8/lib/python3.8/site-packages/flask/app.py", line 882, in full_dispatch_request
    rv = self.handle_user_exception(e)
  File "/home/fayabase/virtualenv/test.fayabase.com/flask_project/3.8/lib/python3.8/site-packages/flask/app.py", line 880, in full_dispatch_request
    rv = self.dispatch_request()
  File "/home/fayabase/virtualenv/test.fayabase.com/flask_project/3.8/lib/python3.8/site-packages/flask/app.py", line 865, in dispatch_request
    return self.ensure_sync(self.view_functions[rule.endpoint])(**view_args)  # type: ignore[no-any-return]
  File "/home/fayabase/test.fayabase.com/flask_project/application.py", line 21, in save_design
    # Save the final image
NameError: name 'uuid' is not defined
[2024-11-21 01:50:43,326] ERROR in app: Exception on /save [POST]
Traceback (most recent call last):
  File "/home/fayabase/virtualenv/test.fayabase.com/flask_project/3.8/lib/python3.8/site-packages/flask/app.py", line 1473, in wsgi_app
    response = self.full_dispatch_request()
  File "/home/fayabase/virtualenv/test.fayabase.com/flask_project/3.8/lib/python3.8/site-packages/flask/app.py", line 882, in full_dispatch_request
    rv = self.handle_user_exception(e)
  File "/home/fayabase/virtualenv/test.fayabase.com/flask_project/3.8/lib/python3.8/site-packages/flask/app.py", line 880, in full_dispatch_request
    rv = self.dispatch_request()
  File "/home/fayabase/virtualenv/test.fayabase.com/flask_project/3.8/lib/python3.8/site-packages/flask/app.py", line 865, in dispatch_request
    return self.ensure_sync(self.view_functions[rule.endpoint])(**view_args)  # type: ignore[no-any-return]
  File "/home/fayabase/test.fayabase.com/flask_project/application.py", line 27, in save_design
    random_filename = f"{uuid.uuid4().hex}.png"
NameError: name 'uuid' is not defined
[2024-11-21 01:53:26,246] ERROR in app: Exception on /save [POST]
Traceback (most recent call last):
  File "/home/fayabase/virtualenv/test.fayabase.com/flask_project/3.8/lib/python3.8/site-packages/flask/app.py", line 1473, in wsgi_app
    response = self.full_dispatch_request()
  File "/home/fayabase/virtualenv/test.fayabase.com/flask_project/3.8/lib/python3.8/site-packages/flask/app.py", line 882, in full_dispatch_request
    rv = self.handle_user_exception(e)
  File "/home/fayabase/virtualenv/test.fayabase.com/flask_project/3.8/lib/python3.8/site-packages/flask/app.py", line 880, in full_dispatch_request
    rv = self.dispatch_request()
  File "/home/fayabase/virtualenv/test.fayabase.com/flask_project/3.8/lib/python3.8/site-packages/flask/app.py", line 865, in dispatch_request
    return self.ensure_sync(self.view_functions[rule.endpoint])(**view_args)  # type: ignore[no-any-return]
  File "/home/fayabase/test.fayabase.com/flask_project/application.py", line 30, in save_design
    save_path = os.path.join("public", random_filename)
NameError: name 'os' is not defined
io.UnsupportedOperation: fileno
io.UnsupportedOperation: fileno
io.UnsupportedOperation: fileno
Traceback (most recent call last):
  File "/home/fayabase/test.fayabase.com/flask_project/passenger_wsgi.py", line 10, in <module>
    from application import app as application 
  File "/home/fayabase/test.fayabase.com/flask_project/application.py", line 29
    random_filename = f"{random.randint(100000, 999999)}.png"
    ^
IndentationError: unexpected indent
Traceback (most recent call last):
  File "/home/fayabase/test.fayabase.com/flask_project/passenger_wsgi.py", line 10, in <module>
    from application import app as application 
  File "/home/fayabase/test.fayabase.com/flask_project/application.py", line 29
    random_filename = f"{random.randint(100000, 999999)}.png"
    ^
IndentationError: unexpected indent
[UID:1801][198682] packetLen < 0
[UID:1801][198433] Child process with pid: 198682 was killed by signal: 15, core dumped: no
Traceback (most recent call last):
  File "/home/fayabase/test.fayabase.com/flask_project/passenger_wsgi.py", line 10, in <module>
    from application import app as application 
  File "/home/fayabase/test.fayabase.com/flask_project/application.py", line 29
    random_filename = f"{random.randint(100000, 999999)}.png"
    ^
IndentationError: unexpected indent
[UID:1801][198772] packetLen < 0
[UID:1801][198433] Child process with pid: 198772 was killed by signal: 15, core dumped: no
io.UnsupportedOperation: fileno
io.UnsupportedOperation: fileno
Traceback (most recent call last):
  File "/home/fayabase/test.fayabase.com/flask_project/passenger_wsgi.py", line 10, in <module>
    from application import app as application 
  File "/home/fayabase/test.fayabase.com/flask_project/application.py", line 43
    return send_file(save_path, mimetype='image/png', as_attachment=True)
                                                                        ^
IndentationError: unindent does not match any outer indentation level
Traceback (most recent call last):
  File "/home/fayabase/test.fayabase.com/flask_project/passenger_wsgi.py", line 10, in <module>
    from application import app as application 
  File "/home/fayabase/test.fayabase.com/flask_project/application.py", line 43
    return send_file(save_path, mimetype='image/png', as_attachment=True)
                                                                        ^
IndentationError: unindent does not match any outer indentation level
[UID:1801][219242] packetLen < 0
